Workbook

Sheet 📋 Raw Data
A1: Date | B1: Month | C1: Segment | D1: Route | E1: Payment | F1: Tickets | G1: Unit Price | H1: Trips | I1: Passengers | J1: Duration (min) | K1: Revenue (MZN)
A2: 46082 | B2: =TEXT(A2,"MMM YYYY") -> Mar 2026 | C2: Estudante | D2: Maputo Centro - Matola | E2: M-Pesa | F2: 460 | G2: 25 | H2: 1380 | I2: 64308 | J2: 40 | K2: 11500
A3: 46082 | B3: =TEXT(A3,"MMM YYYY") -> Mar 2026 | C3: Trabalhador | D3: Matola - Boane | E3: e-Mola | F3: 1472 | G3: 75 | H3: 1472 | I3: 59616 | J3: 74 | K3: 110400
A4: 46082 | B4: =TEXT(A4,"MMM YYYY") -> Mar 2026 | C4: Turista | D4: Machava - Marracuene | E4: e-Mola | F4: 460 | G4: 75 | H4: 828 | I4: 19872 | J4: 71 | K4: 34500
A5: 46082 | B5: =TEXT(A5,"MMM YYYY") -> Mar 2026 | C5: Turista | D5: Maputo Centro - KaMavota | E5: Numerário | F5: 1840 | G5: 100 | H5: 1104 | I5: 29164 | J5: 21 | K5: 184000
A6: 46082 | B6: =TEXT(A6,"MMM YYYY") -> Mar 2026 | C6: Turista | D6: Maputo Centro - Matola | E6: M-Pesa | F6: 1564 | G6: 75 | H6: 1380 | I6: 64308 | J6: 40 | K6: 117300
A7: 46083 | B7: =TEXT(A7,"MMM YYYY") -> Mar 2026 | C7: Estudante | D7: Machava - Marracuene | E7: Numerário | F7: 1288 | G7: 50 | H7: 460 | I7: 4876 | J7: 75 | K7: 64400
A8: 46083 | B8: =TEXT(A8,"MMM YYYY") -> Mar 2026 | C8: Estudante | D8: Maputo Centro - KaMavota | E8: M-Pesa | F8: 736 | G8: 50 | H8: 1288 | I8: 30176 | J8: 32 | K8: 36800
A9: 46083 | B9: =TEXT(A9,"MMM YYYY") -> Mar 2026 | C9: Estudante | D9: Matola - Boane | E9: Numerário | F9: 92 | G9: 50 | H9: 1288 | I9: 23644 | J9: 55 | K9: 4600
A10: 46083 | B10: =TEXT(A10,"MMM YYYY") -> Mar 2026 | C10: Trabalhador | D10: Maputo Centro - KaMavota | E10: e-Mola | F10: 736 | G10: 50 | H10: 1288 | I10: 30176 | J10: 32 | K10: 36800
A11: 46083 | B11: =TEXT(A11,"MMM YYYY") -> Mar 2026 | C11: Turista | D11: Machava - Marracuene | E11: M-Pesa | F11: 1288 | G11: 75 | H11: 460 | I11: 4876 | J11: 75 | K11: 96600
A12: 46083 | B12: =TEXT(A12,"MMM YYYY") -> Mar 2026 | C12: Turista | D12: Maputo Centro - Machava | E12: M-Pesa | F12: 736 | G12: 75 | H12: 1288 | I12: 36984 | J12: 39 | K12: 55200
A13: 46083 | B13: =TEXT(A13,"MMM YYYY") -> Mar 2026 | C13: Turista | D13: Matola - Boane | E13: M-Pesa | F13: 828 | G13: 50 | H13: 1288 | I13: 23644 | J13: 55 | K13: 41400
... A514: 46173 | B514: =TEXT(A514,"MMM YYYY") -> May 2026 | C514: Turista | D514: Maputo Centro - Machava | E514: e-Mola | F514: 1104 | G514: 75 | H514: 920 | I514: 5980 | J514: 44 | K514: 82800

Sheet 📊 MoM Summary
B2: 🚌 MOZCHAPA100 — Month-on-Month Operations Summary
B4: 🔵 Blue = hardcoded input 🖤 Black = formula 🟢 Green = cross-sheet link
B6: ⚙️ ASSUMPTIONS (change these cells to update the whole sheet)
B7: Label | C7: Value | D7: Notes
B8: Mar 2026 — days in month | C8: 31 | D8: March has 31 days
B9: Apr 2026 — days in month | C9: 30 | D9: April has 30 days
B10: May 2026 — days in month | C10: 31 | D10: May has 31 days
B11: Mar 2026 — month number | C11: 3 | D11: Used in SUMPRODUCT formulas
B12: Apr 2026 — month number | C12: 4 | D12: Used in SUMPRODUCT formulas
B13: May 2026 — month number | C13: 5 | D13: Used in SUMPRODUCT formulas
B15: 📊 MONTH-ON-MONTH TABLE — Total + by Segment
B16: Metric / Segment | C16: Mar 2026 (M1) | D16: Apr 2026 (M2) | E16: May 2026 (M3) | F16: Apr vs Mar % | G16: May vs Apr % | H16: Apr vs Mar Abs Diff | I16: May vs Apr Abs Diff | J16: Daily Avg Mar | K16: Daily Avg Apr | L16: Daily Avg May | M16: Daily Avg May vs Apr Δ
B17: ▶ Revenue (MZN) | C17: =SUMPRODUCT(('📋 Raw Data'!$K$2:$K$514)*(YEAR('📋 Raw Data'!$A$2:$A$514)=2026)*(MONTH('📋 Raw Data'!$A$2:$A$514)=$C$11)) -> 10397840 | D17: =SUMPRODUCT(('📋 Raw Data'!$K$2:$K$514)*(YEAR('📋 Raw Data'!$A$2:$A$514)=2026)*(MONTH('📋 Raw Data'!$A$2:$A$514)=$C$12)) -> 10089640 | E17: =SUMPRODUCT(('📋 Raw Data'!$K$2:$K$514)*(YEAR('📋 Raw Data'!$A$2:$A$514)=2026)*(MONTH('📋 Raw Data'!$A$2:$A$514)=$C$13)) -> 9609400 | F17: =D17/C17-1 -> -0.029640772 | G17: =E17/D17-1 -> -0.047597337 | H17: =D17-C17 -> -308200 | I17: =E17-D17 -> -480240 | J17: =C17/$C$8 -> 335414.19 | K17: =D17/$C$9 -> 336321.33 | L17: =E17/$C$10 -> 309980.65 | M17: =L17-K17 -> -26340.688
B18: └ Estudante | C18: =SUMPRODUCT(('📋 Raw Data'!$K$2:$K$514)*(YEAR('📋 Raw Data'!$A$2:$A$514)=2026)*(MONTH('📋 Raw Data'!$A$2:$A$514)=$C$11)*('📋 Raw Data'!$C$2:$C$514="Estudante")) -> 3317520 | D18: =SUMPRODUCT(('📋 Raw Data'!$K$2:$K$514)*(YEAR('📋 Raw Data'!$A$2:$A$514)=2026)*(MONTH('📋 Raw Data'!$A$2:$A$514)=$C$12)*('📋 Raw Data'!$C$2:$C$514="Estudante")) -> 3670340 | E18: =SUMPRODUCT(('📋 Raw Data'!$K$2:$K$514)*(YEAR('📋 Raw Data'!$A$2:$A$514)=2026)*(MONTH('📋 Raw Data'!$A$2:$A$514)=$C$13)*('📋 Raw Data'!$C$2:$C$514="Estudante")) -> 3220460 | F18: =D18/C18-1 -> 0.10635053 | G18: =E18/D18-1 -> -0.12257175 | H18: =D18-C18 -> 352820 | I18: =E18-D18 -> -449880 | J18: =C18/$C$8 -> 107016.77 | K18: =D18/$C$9 -> 122344.67 | L18: =E18/$C$10 -> 103885.81 | M18: =L18-K18 -> -18458.86
B19: └ Trabalhador | C19: =SUMPRODUCT(('📋 Raw Data'!$K$2:$K$514)*(YEAR('📋 Raw Data'!$A$2:$A$514)=2026)*(MONTH('📋 Raw Data'!$A$2:$A$514)=$C$11)*('📋 Raw Data'!$C$2:$C$514="Trabalhador")) -> 3131220 | D19: =SUMPRODUCT(('📋 Raw Data'!$K$2:$K$514)*(YEAR('📋 Raw Data'!$A$2:$A$514)=2026)*(MONTH('📋 Raw Data'!$A$2:$A$514)=$C$12)*('📋 Raw Data'!$C$2:$C$514="Trabalhador")) -> 3116960 | E19: =SUMPRODUCT(('📋 Raw Data'!$K$2:$K$514)*(YEAR('📋 Raw Data'!$A$2:$A$514)=2026)*(MONTH('📋 Raw Data'!$A$2:$A$514)=$C$13)*('📋 Raw Data'!$C$2:$C$514="Trabalhador")) -> 2526320 | F19: =D19/C19-1 -> -0.0045541354 | G19: =E19/D19-1 -> -0.18949233 | H19: =D19-C19 -> -14260 | I19: =E19-D19 -> -590640 | J19: =C19/$C$8 -> 101007.1 | K19: =D19/$C$9 -> 103898.67 | L19: =E19/$C$10 -> 81494.194 | M19: =L19-K19 -> -22404.473
B20: └ Turista | C20: =SUMPRODUCT(('📋 Raw Data'!$K$2:$K$514)*(YEAR('📋 Raw Data'!$A$2:$A$514)=2026)*(MONTH('📋 Raw Data'!$A$2:$A$514)=$C$11)*('📋 Raw Data'!$C$2:$C$514="Turista")) -> 3949100 | D20: =SUMPRODUCT(('📋 Raw Data'!$K$2:$K$514)*(YEAR('📋 Raw Data'!$A$2:$A$514)=2026)*(MONTH('📋 Raw Data'!$A$2:$A$514)=$C$12)*('📋 Raw Data'!$C$2:$C$514="Turista")) -> 3302340 | E20: =SUMPRODUCT(('📋 Raw Data'!$K$2:$K$514)*(YEAR('📋 Raw Data'!$A$2:$A$514)=2026)*(MONTH('📋 Raw Data'!$A$2:$A$514)=$C$13)*('📋 Raw Data'!$C$2:$C$514="Turista")) -> 3862620 | F20: =D20/C20-1 -> -0.16377402 | G20: =E20/D20-1 -> 0.16966151 | H20: =D20-C20 -> -646760 | I20: =E20-D20 -> 560280 | J20: =C20/$C$8 -> 127390.32 | K20: =D20/$C$9 -> 110078 | L20: =E20/$C$10 -> 124600.65 | M20: =L20-K20 -> 14522.645
B22: ▶ Trips | C22: =SUMPRODUCT(('📋 Raw Data'!$H$2:$H$514)*(YEAR('📋 Raw Data'!$A$2:$A$514)=2026)*(MONTH('📋 Raw Data'!$A$2:$A$514)=$C$11)) -> 181056 | D22: =SUMPRODUCT(('📋 Raw Data'!$H$2:$H$514)*(YEAR('📋 Raw Data'!$A$2:$A$514)=2026)*(MONTH('📋 Raw Data'!$A$2:$A$514)=$C$12)) -> 167716 | E22: =SUMPRODUCT(('📋 Raw Data'!$H$2:$H$514)*(YEAR('📋 Raw Data'!$A$2:$A$514)=2026)*(MONTH('📋 Raw Data'!$A$2:$A$514)=$C$13)) -> 171212 | F22: =D22/C22-1 -> -0.073678862 | G22: =E22/D22-1 -> 0.020844761 | H22: =D22-C22 -> -13340 | I22: =E22-D22 -> 3496 | J22: =C22/$C$8 -> 5840.5161 | K22: =D22/$C$9 -> 5590.5333 | L22: =E22/$C$10 -> 5522.9677 | M22: =L22-K22 -> -67.565591
B23: └ Estudante | C23: =SUMPRODUCT(('📋 Raw Data'!$H$2:$H$514)*(YEAR('📋 Raw Data'!$A$2:$A$514)=2026)*(MONTH('📋 Raw Data'!$A$2:$A$514)=$C$11)*('📋 Raw Data'!$C$2:$C$514="Estudante")) -> 56764 | D23: =SUMPRODUCT(('📋 Raw Data'!$H$2:$H$514)*(YEAR('📋 Raw Data'!$A$2:$A$514)=2026)*(MONTH('📋 Raw Data'!$A$2:$A$514)=$C$12)*('📋 Raw Data'!$C$2:$C$514="Estudante")) -> 58328 | E23: =SUMPRODUCT(('📋 Raw Data'!$H$2:$H$514)*(YEAR('📋 Raw Data'!$A$2:$A$514)=2026)*(MONTH('📋 Raw Data'!$A$2:$A$514)=$C$13)*('📋 Raw Data'!$C$2:$C$514="Estudante")) -> 58328 | F23: =D23/C23-1 -> 0.027552674 | G23: =E23/D23-1 -> 0 | H23: =D23-C23 -> 1564 | I23: =E23-D23 -> 0 | J23: =C23/$C$8 -> 1831.0968 | K23: =D23/$C$9 -> 1944.2667 | L23: =E23/$C$10 -> 1881.5484 | M23: =L23-K23 -> -62.71828
B24: └ Trabalhador | C24: =SUMPRODUCT(('📋 Raw Data'!$H$2:$H$514)*(YEAR('📋 Raw Data'!$A$2:$A$514)=2026)*(MONTH('📋 Raw Data'!$A$2:$A$514)=$C$11)*('📋 Raw Data'!$C$2:$C$514="Trabalhador")) -> 54556 | D24: =SUMPRODUCT(('📋 Raw Data'!$H$2:$H$514)*(YEAR('📋 Raw Data'!$A$2:$A$514)=2026)*(MONTH('📋 Raw Data'!$A$2:$A$514)=$C$12)*('📋 Raw Data'!$C$2:$C$514="Trabalhador")) -> 50508 | E24: =SUMPRODUCT(('📋 Raw Data'!$H$2:$H$514)*(YEAR('📋 Raw Data'!$A$2:$A$514)=2026)*(MONTH('📋 Raw Data'!$A$2:$A$514)=$C$13)*('📋 Raw Data'!$C$2:$C$514="Trabalhador")) -> 42872 | F24: =D24/C24-1 -> -0.074198988 | G24: =E24/D24-1 -> -0.15118397 | H24: =D24-C24 -> -4048 | I24: =E24-D24 -> -7636 | J24: =C24/$C$8 -> 1759.871 | K24: =D24/$C$9 -> 1683.6 | L24: =E24/$C$10 -> 1382.9677 | M24: =L24-K24 -> -300.63226
B25: └ Turista | C25: =SUMPRODUCT(('📋 Raw Data'!$H$2:$H$514)*(YEAR('📋 Raw Data'!$A$2:$A$514)=2026)*(MONTH('📋 Raw Data'!$A$2:$A$514)=$C$11)*('📋 Raw Data'!$C$2:$C$514="Turista")) -> 69736 | D25: =SUMPRODUCT(('📋 Raw Data'!$H$2:$H$514)*(YEAR('📋 Raw Data'!$A$2:$A$514)=2026)*(MONTH('📋 Raw Data'!$A$2:$A$514)=$C$12)*('📋 Raw Data'!$C$2:$C$514="Turista")) -> 58880 | E25: =SUMPRODUCT(('📋 Raw Data'!$H$2:$H$514)*(YEAR('📋 Raw Data'!$A$2:$A$514)=2026)*(MONTH('📋 Raw Data'!$A$2:$A$514)=$C$13)*('📋 Raw Data'!$C$2:$C$514="Turista")) -> 70012 | F25: =D25/C25-1 -> -0.15567282 | G25: =E25/D25-1 -> 0.1890625 | H25: =D25-C25 -> -10856 | I25: =E25-D25 -> 11132 | J25: =C25/$C$8 -> 2249.5484 | K25: =D25/$C$9 -> 1962.6667 | L25: =E25/$C$10 -> 2258.4516 | M25: =L25-K25 -> 295.78495
B27: ▶ Passengers | C27: =SUMPRODUCT(('📋 Raw Data'!$I$2:$I$514)*(YEAR('📋 Raw Data'!$A$2:$A$514)=2026)*(MONTH('📋 Raw Data'!$A$2:$A$514)=$C$11)) -> 5116948 | D27: =SUMPRODUCT(('📋 Raw Data'!$I$2:$I$514)*(YEAR('📋 Raw Data'!$A$2:$A$514)=2026)*(MONTH('📋 Raw Data'!$A$2:$A$514)=$C$12)) -> 4722820 | E27: =SUMPRODUCT(('📋 Raw Data'!$I$2:$I$514)*(YEAR('📋 Raw Data'!$A$2:$A$514)=2026)*(MONTH('📋 Raw Data'!$A$2:$A$514)=$C$13)) -> 4894124 | F27: =D27/C27-1 -> -0.077024039 | G27: =E27/D27-1 -> 0.03627155 | H27: =D27-C27 -> -394128 | I27: =E27-D27 -> 171304 | J27: =C27/$C$8 -> 165062.84 | K27: =D27/$C$9 -> 157427.33 | L27: =E27/$C$10 -> 157874.97 | M27: =L27-K27 -> 447.63441
B28: └ Estudante | C28: =SUMPRODUCT(('📋 Raw Data'!$I$2:$I$514)*(YEAR('📋 Raw Data'!$A$2:$A$514)=2026)*(MONTH('📋 Raw Data'!$A$2:$A$514)=$C$11)*('📋 Raw Data'!$C$2:$C$514="Estudante")) -> 1509812 | D28: =SUMPRODUCT(('📋 Raw Data'!$I$2:$I$514)*(YEAR('📋 Raw Data'!$A$2:$A$514)=2026)*(MONTH('📋 Raw Data'!$A$2:$A$514)=$C$12)*('📋 Raw Data'!$C$2:$C$514="Estudante")) -> 1601996 | E28: =SUMPRODUCT(('📋 Raw Data'!$I$2:$I$514)*(YEAR('📋 Raw Data'!$A$2:$A$514)=2026)*(MONTH('📋 Raw Data'!$A$2:$A$514)=$C$13)*('📋 Raw Data'!$C$2:$C$514="Estudante")) -> 1676884 | F28: =D28/C28-1 -> 0.061056608 | G28: =E28/D28-1 -> 0.046746684 | H28: =D28-C28 -> 92184 | I28: =E28-D28 -> 74888 | J28: =C28/$C$8 -> 48703.613 | K28: =D28/$C$9 -> 53399.867 | L28: =E28/$C$10 -> 54093.032 | M28: =L28-K28 -> 693.16559
B29: └ Trabalhador | C29: =SUMPRODUCT(('📋 Raw Data'!$I$2:$I$514)*(YEAR('📋 Raw Data'!$A$2:$A$514)=2026)*(MONTH('📋 Raw Data'!$A$2:$A$514)=$C$11)*('📋 Raw Data'!$C$2:$C$514="Trabalhador")) -> 1599604 | D29: =SUMPRODUCT(('📋 Raw Data'!$I$2:$I$514)*(YEAR('📋 Raw Data'!$A$2:$A$514)=2026)*(MONTH('📋 Raw Data'!$A$2:$A$514)=$C$12)*('📋 Raw Data'!$C$2:$C$514="Trabalhador")) -> 1192872 | E29: =SUMPRODUCT(('📋 Raw Data'!$I$2:$I$514)*(YEAR('📋 Raw Data'!$A$2:$A$514)=2026)*(MONTH('📋 Raw Data'!$A$2:$A$514)=$C$13)*('📋 Raw Data'!$C$2:$C$514="Trabalhador")) -> 1207776 | F29: =D29/C29-1 -> -0.25427043 | G29: =E29/D29-1 -> 0.012494216 | H29: =D29-C29 -> -406732 | I29: =E29-D29 -> 14904 | J29: =C29/$C$8 -> 51600.129 | K29: =D29/$C$9 -> 39762.4 | L29: =E29/$C$10 -> 38960.516 | M29: =L29-K29 -> -801.88387
B30: └ Turista | C30: =SUMPRODUCT(('📋 Raw Data'!$I$2:$I$514)*(YEAR('📋 Raw Data'!$A$2:$A$514)=2026)*(MONTH('📋 Raw Data'!$A$2:$A$514)=$C$11)*('📋 Raw Data'!$C$2:$C$514="Turista")) -> 2007532 | D30: =SUMPRODUCT(('📋 Raw Data'!$I$2:$I$514)*(YEAR('📋 Raw Data'!$A$2:$A$514)=2026)*(MONTH('📋 Raw Data'!$A$2:$A$514)=$C$12)*('📋 Raw Data'!$C$2:$C$514="Turista")) -> 1927952 | E30: =SUMPRODUCT(('📋 Raw Data'!$I$2:$I$514)*(YEAR('📋 Raw Data'!$A$2:$A$514)=2026)*(MONTH('📋 Raw Data'!$A$2:$A$514)=$C$13)*('📋 Raw Data'!$C$2:$C$514="Turista")) -> 2009464 | F30: =D30/C30-1 -> -0.039640713 | G30: =E30/D30-1 -> 0.042279061 | H30: =D30-C30 -> -79580 | I30: =E30-D30 -> 81512 | J30: =C30/$C$8 -> 64759.097 | K30: =D30/$C$9 -> 64265.067 | L30: =E30/$C$10 -> 64821.419 | M30: =L30-K30 -> 556.35269
B32: ▶ Tickets Sold | C32: =SUMPRODUCT(('📋 Raw Data'!$F$2:$F$514)*(YEAR('📋 Raw Data'!$A$2:$A$514)=2026)*(MONTH('📋 Raw Data'!$A$2:$A$514)=$C$11)) -> 177284 | D32: =SUMPRODUCT(('📋 Raw Data'!$F$2:$F$514)*(YEAR('📋 Raw Data'!$A$2:$A$514)=2026)*(MONTH('📋 Raw Data'!$A$2:$A$514)=$C$12)) -> 174616 | E32: =SUMPRODUCT(('📋 Raw Data'!$F$2:$F$514)*(YEAR('📋 Raw Data'!$A$2:$A$514)=2026)*(MONTH('📋 Raw Data'!$A$2:$A$514)=$C$13)) -> 166704 | F32: =D32/C32-1 -> -0.015049299 | G32: =E32/D32-1 -> -0.045310854 | H32: =D32-C32 -> -2668 | I32: =E32-D32 -> -7912 | J32: =C32/$C$8 -> 5718.8387 | K32: =D32/$C$9 -> 5820.5333 | L32: =E32/$C$10 -> 5377.5484 | M32: =L32-K32 -> -442.98495
B33: └ Estudante | C33: =SUMPRODUCT(('📋 Raw Data'!$F$2:$F$514)*(YEAR('📋 Raw Data'!$A$2:$A$514)=2026)*(MONTH('📋 Raw Data'!$A$2:$A$514)=$C$11)*('📋 Raw Data'!$C$2:$C$514="Estudante")) -> 52992 | D33: =SUMPRODUCT(('📋 Raw Data'!$F$2:$F$514)*(YEAR('📋 Raw Data'!$A$2:$A$514)=2026)*(MONTH('📋 Raw Data'!$A$2:$A$514)=$C$12)*('📋 Raw Data'!$C$2:$C$514="Estudante")) -> 59800 | E33: =SUMPRODUCT(('📋 Raw Data'!$F$2:$F$514)*(YEAR('📋 Raw Data'!$A$2:$A$514)=2026)*(MONTH('📋 Raw Data'!$A$2:$A$514)=$C$13)*('📋 Raw Data'!$C$2:$C$514="Estudante")) -> 55476 | F33: =D33/C33-1 -> 0.12847222 | G33: =E33/D33-1 -> -0.072307692 | H33: =D33-C33 -> 6808 | I33: =E33-D33 -> -4324 | J33: =C33/$C$8 -> 1709.4194 | K33: =D33/$C$9 -> 1993.3333 | L33: =E33/$C$10 -> 1789.5484 | M33: =L33-K33 -> -203.78495
B34: └ Trabalhador | C34: =SUMPRODUCT(('📋 Raw Data'!$F$2:$F$514)*(YEAR('📋 Raw Data'!$A$2:$A$514)=2026)*(MONTH('📋 Raw Data'!$A$2:$A$514)=$C$11)*('📋 Raw Data'!$C$2:$C$514="Trabalhador")) -> 60168 | D34: =SUMPRODUCT(('📋 Raw Data'!$F$2:$F$514)*(YEAR('📋 Raw Data'!$A$2:$A$514)=2026)*(MONTH('📋 Raw Data'!$A$2:$A$514)=$C$12)*('📋 Raw Data'!$C$2:$C$514="Trabalhador")) -> 56488 | E34: =SUMPRODUCT(('📋 Raw Data'!$F$2:$F$514)*(YEAR('📋 Raw Data'!$A$2:$A$514)=2026)*(MONTH('📋 Raw Data'!$A$2:$A$514)=$C$13)*('📋 Raw Data'!$C$2:$C$514="Trabalhador")) -> 44896 | F34: =D34/C34-1 -> -0.06116208 | G34: =E34/D34-1 -> -0.20521173 | H34: =D34-C34 -> -3680 | I34: =E34-D34 -> -11592 | J34: =C34/$C$8 -> 1940.9032 | K34: =D34/$C$9 -> 1882.9333 | L34: =E34/$C$10 -> 1448.2581 | M34: =L34-K34 -> -434.67527
B35: └ Turista | C35: =SUMPRODUCT(('📋 Raw Data'!$F$2:$F$514)*(YEAR('📋 Raw Data'!$A$2:$A$514)=2026)*(MONTH('📋 Raw Data'!$A$2:$A$514)=$C$11)*('📋 Raw Data'!$C$2:$C$514="Turista")) -> 64124 | D35: =SUMPRODUCT(('📋 Raw Data'!$F$2:$F$514)*(YEAR('📋 Raw Data'!$A$2:$A$514)=2026)*(MONTH('📋 Raw Data'!$A$2:$A$514)=$C$12)*('📋 Raw Data'!$C$2:$C$514="Turista")) -> 58328 | E35: =SUMPRODUCT(('📋 Raw Data'!$F$2:$F$514)*(YEAR('📋 Raw Data'!$A$2:$A$514)=2026)*(MONTH('📋 Raw Data'!$A$2:$A$514)=$C$13)*('📋 Raw Data'!$C$2:$C$514="Turista")) -> 66332 | F35: =D35/C35-1 -> -0.090387374 | G35: =E35/D35-1 -> 0.13722397 | H35: =D35-C35 -> -5796 | I35: =E35-D35 -> 8004 | J35: =C35/$C$8 -> 2068.5161 | K35: =D35/$C$9 -> 1944.2667 | L35: =E35/$C$10 -> 2139.7419 | M35: =L35-K35 -> 195.47527
B38: 📖 HOW THE FORMULAS WORK
B39: SUMPRODUCT totals | C39: SUMPRODUCT((Revenue)*(YEAR(Date)=2026)*(MONTH(Date)=3)) | H39: Adds all Revenue values where year=2026 and month=March
B40: With segment filter | C40: SUMPRODUCT((Revenue)*(YEAR(Date)=2026)*(MONTH(Date)=3)*(Segment="Estudante")) | H40: Same, but only for Estudante rows
B41: % change | C41: (Apr / Mar) - 1 | H41: Apr÷Mar minus 1 → percentage growth (positive = growth, negative = decline)
B42: Absolute diff | C42: Apr - Mar | H42: Apr minus Mar → raw difference in units
B43: Daily average | C43: C17 / 31 [days in March] | H43: Total ÷ days in month → average per day
B44: Daily avg delta | C44: L17 - K17 [Daily Avg May - Daily Avg Apr] | H44: May daily avg minus Apr daily avg → improvement per day
B46: 🕐 ROUTE DURATION INSIGHT — Avg Trip Duration by Route (min)
B47: Route | C47: Mar 2026 (M1) | D47: Apr 2026 (M2) | E47: May 2026 (M3) | F47: Apr vs Mar % | G47: May vs Apr % | H47: Apr vs Mar Abs (min) | I47: May vs Apr Abs (min) | J47: Longest Month
B48: Machava - Marracuene | C48: =AVERAGEIFS('📋 Raw Data'!$J$2:$J$514,'📋 Raw Data'!$D$2:$D$514,$B48,'📋 Raw Data'!$B$2:$B$514,"Mar 2026") -> 82.517241 | D48: =AVERAGEIFS('📋 Raw Data'!$J$2:$J$514,'📋 Raw Data'!$D$2:$D$514,$B48,'📋 Raw Data'!$B$2:$B$514,"Apr 2026") -> 79.484848 | E48: =AVERAGEIFS('📋 Raw Data'!$J$2:$J$514,'📋 Raw Data'!$D$2:$D$514,$B48,'📋 Raw Data'!$B$2:$B$514,"May 2026") -> 81.65625 | F48: =D48/C48-1 -> -0.036748598 | G48: =E48/D48-1 -> 0.027318433 | H48: =D48-C48 -> -3.0323929 | I48: =E48-D48 -> 2.1714015 | J48: =IF(AND(C48>=D48,C48>=E48),"Mar",IF(D48>=E48,"Apr","May")) -> Mar
B49: Maputo Centro - KaMavota | C49: =AVERAGEIFS('📋 Raw Data'!$J$2:$J$514,'📋 Raw Data'!$D$2:$D$514,$B49,'📋 Raw Data'!$B$2:$B$514,"Mar 2026") -> 24.918919 | D49: =AVERAGEIFS('📋 Raw Data'!$J$2:$J$514,'📋 Raw Data'!$D$2:$D$514,$B49,'📋 Raw Data'!$B$2:$B$514,"Apr 2026") -> 24.958333 | E49: =AVERAGEIFS('📋 Raw Data'!$J$2:$J$514,'📋 Raw Data'!$D$2:$D$514,$B49,'📋 Raw Data'!$B$2:$B$514,"May 2026") -> 26.75 | F49: =D49/C49-1 -> 0.0015817064 | G49: =E49/D49-1 -> 0.071786311 | H49: =D49-C49 -> 0.039414414 | I49: =E49-D49 -> 1.7916667 | J49: =IF(AND(C49>=D49,C49>=E49),"Mar",IF(D49>=E49,"Apr","May")) -> May
B50: Maputo Centro - Machava | C50: =AVERAGEIFS('📋 Raw Data'!$J$2:$J$514,'📋 Raw Data'!$D$2:$D$514,$B50,'📋 Raw Data'!$B$2:$B$514,"Mar 2026") -> 33.37931 | D50: =AVERAGEIFS('📋 Raw Data'!$J$2:$J$514,'📋 Raw Data'!$D$2:$D$514,$B50,'📋 Raw Data'!$B$2:$B$514,"Apr 2026") -> 34.966667 | E50: =AVERAGEIFS('📋 Raw Data'!$J$2:$J$514,'📋 Raw Data'!$D$2:$D$514,$B50,'📋 Raw Data'!$B$2:$B$514,"May 2026") -> 36.512821 | F50: =D50/C50-1 -> 0.047555096 | G50: =E50/D50-1 -> 0.044217936 | H50: =D50-C50 -> 1.5873563 | I50: =E50-D50 -> 1.5461538 | J50: =IF(AND(C50>=D50,C50>=E50),"Mar",IF(D50>=E50,"Apr","May")) -> May
...

Sheet 🗺️ By Route
B2: 🗺️ MOZCHAPA100 — Revenue by Route (Month-on-Month)
B4: 💰 Revenue by Route
B5: Route | C5: Mar 2026 | D5: Apr 2026 | E5: May 2026 | F5: Apr vs Mar % | G5: May vs Apr % | H5: Apr vs Mar Abs | I5: May vs Apr Abs | J5: May Share %
B6: Machava - Marracuene | C6: =SUMPRODUCT(('📋 Raw Data'!$K$2:$K$514)*(YEAR('📋 Raw Data'!$A$2:$A$514)=2026)*(MONTH('📋 Raw Data'!$A$2:$A$514)=3)*('📋 Raw Data'!$D$2:$D$514="Machava - Marracuene")) -> 1754900 | D6: =SUMPRODUCT(('📋 Raw Data'!$K$2:$K$514)*(YEAR('📋 Raw Data'!$A$2:$A$514)=2026)*(MONTH('📋 Raw Data'!$A$2:$A$514)=4)*('📋 Raw Data'!$D$2:$D$514="Machava - Marracuene")) -> 1872660 | E6: =SUMPRODUCT(('📋 Raw Data'!$K$2:$K$514)*(YEAR('📋 Raw Data'!$A$2:$A$514)=2026)*(MONTH('📋 Raw Data'!$A$2:$A$514)=5)*('📋 Raw Data'!$D$2:$D$514="Machava - Marracuene")) -> 1925100 | F6: =D6/C6-1 -> 0.067103539 | G6: =E6/D6-1 -> 0.028002948 | H6: =D6-C6 -> 117760 | I6: =E6-D6 -> 52440 | J6: =E6/$E$11 -> 0.20033509
B7: Maputo Centro - KaMavota | C7: =SUMPRODUCT(('📋 Raw Data'!$K$2:$K$514)*(YEAR('📋 Raw Data'!$A$2:$A$514)=2026)*(MONTH('📋 Raw Data'!$A$2:$A$514)=3)*('📋 Raw Data'!$D$2:$D$514="Maputo Centro - KaMavota")) -> 2069080 | D7: =SUMPRODUCT(('📋 Raw Data'!$K$2:$K$514)*(YEAR('📋 Raw Data'!$A$2:$A$514)=2026)*(MONTH('📋 Raw Data'!$A$2:$A$514)=4)*('📋 Raw Data'!$D$2:$D$514="Maputo Centro - KaMavota")) -> 3241620 | E7: =SUMPRODUCT(('📋 Raw Data'!$K$2:$K$514)*(YEAR('📋 Raw Data'!$A$2:$A$514)=2026)*(MONTH('📋 Raw Data'!$A$2:$A$514)=5)*('📋 Raw Data'!$D$2:$D$514="Maputo Centro - KaMavota")) -> 1742020 | F7: =D7/C7-1 -> 0.56669631 | G7: =E7/D7-1 -> -0.4626082 | H7: =D7-C7 -> 1172540 | I7: =E7-D7 -> -1499600 | J7: =E7/$E$11 -> 0.18128291
B8: Maputo Centro - Machava | C8: =SUMPRODUCT(('📋 Raw Data'!$K$2:$K$514)*(YEAR('📋 Raw Data'!$A$2:$A$514)=2026)*(MONTH('📋 Raw Data'!$A$2:$A$514)=3)*('📋 Raw Data'!$D$2:$D$514="Maputo Centro - Machava")) -> 1552500 | D8: =SUMPRODUCT(('📋 Raw Data'!$K$2:$K$514)*(YEAR('📋 Raw Data'!$A$2:$A$514)=2026)*(MONTH('📋 Raw Data'!$A$2:$A$514)=4)*('📋 Raw Data'!$D$2:$D$514="Maputo Centro - Machava")) -> 2281600 | E8: =SUMPRODUCT(('📋 Raw Data'!$K$2:$K$514)*(YEAR('📋 Raw Data'!$A$2:$A$514)=2026)*(MONTH('📋 Raw Data'!$A$2:$A$514)=5)*('📋 Raw Data'!$D$2:$D$514="Maputo Centro - Machava")) -> 2110940 | F8: =D8/C8-1 -> 0.46962963 | G8: =E8/D8-1 -> -0.074798387 | H8: =D8-C8 -> 729100 | I8: =E8-D8 -> -170660 | J8: =E8/$E$11 -> 0.21967449
B9: Maputo Centro - Matola | C9: =SUMPRODUCT(('📋 Raw Data'!$K$2:$K$514)*(YEAR('📋 Raw Data'!$A$2:$A$514)=2026)*(MONTH('📋 Raw Data'!$A$2:$A$514)=3)*('📋 Raw Data'!$D$2:$D$514="Maputo Centro - Matola")) -> 1937060 | D9: =SUMPRODUCT(('📋 Raw Data'!$K$2:$K$514)*(YEAR('📋 Raw Data'!$A$2:$A$514)=2026)*(MONTH('📋 Raw Data'!$A$2:$A$514)=4)*('📋 Raw Data'!$D$2:$D$514="Maputo Centro - Matola")) -> 1413580 | E9: =SUMPRODUCT(('📋 Raw Data'!$K$2:$K$514)*(YEAR('📋 Raw Data'!$A$2:$A$514)=2026)*(MONTH('📋 Raw Data'!$A$2:$A$514)=5)*('📋 Raw Data'!$D$2:$D$514="Maputo Centro - Matola")) -> 2113700 | F9: =D9/C9-1 -> -0.2702446 | G9: =E9/D9-1 -> 0.49528148 | H9: =D9-C9 -> -523480 | I9: =E9-D9 -> 700120 | J9: =E9/$E$11 -> 0.2199617
B10: Matola - Boane | C10: =SUMPRODUCT(('📋 Raw Data'!$K$2:$K$514)*(YEAR('📋 Raw Data'!$A$2:$A$514)=2026)*(MONTH('📋 Raw Data'!$A$2:$A$514)=3)*('📋 Raw Data'!$D$2:$D$514="Matola - Boane")) -> 3084300 | D10: =SUMPRODUCT(('📋 Raw Data'!$K$2:$K$514)*(YEAR('📋 Raw Data'!$A$2:$A$514)=2026)*(MONTH('📋 Raw Data'!$A$2:$A$514)=4)*('📋 Raw Data'!$D$2:$D$514="Matola - Boane")) -> 1280180 | E10: =SUMPRODUCT(('📋 Raw Data'!$K$2:$K$514)*(YEAR('📋 Raw Data'!$A$2:$A$514)=2026)*(MONTH('📋 Raw Data'!$A$2:$A$514)=5)*('📋 Raw Data'!$D$2:$D$514="Matola - Boane")) -> 1717640 | F10: =D10/C10-1 -> -0.58493661 | G10: =E10/D10-1 -> 0.34171757 | H10: =D10-C10 -> -1804120 | I10: =E10-D10 -> 437460 | J10: =E10/$E$11 -> 0.17874581
B11: TOTAL | C11: =SUM(C6:C10) -> 10397840 | D11: =SUM(D6:D10) -> 10089640 | E11: =SUM(E6:E10) -> 9609400 | F11: =D11/C11-1 -> -0.029640772 | G11: =E11/D11-1 -> -0.047597337 | H11: =D11-C11 -> -308200 | I11: =E11-D11 -> -480240

Sheet 📅 Daily Trends
B1: 📅 MOZCHAPA100 — Daily Operations Trend (Mar–May 2026) | I1: 💳 Daily Revenue by Payment Type · 7-Day Rolling Average
B2: Date | C2: Month | D2: Revenue (MZN) | E2: Trips | F2: Passengers | G2: Tickets | J2: M-Pesa Rev (MZN) | K2: M-Pesa 7d Avg | L2: e-Mola Rev (MZN) | M2: e-Mola 7d Avg | N2: Numerário Rev (MZN) | O2: Numerário 7d Avg
B3: 46082 | C3: =TEXT(B3,"MMM") -> Mar | D3: =SUMPRODUCT(('📋 Raw Data'!$K$2:$K$514)*(('📋 Raw Data'!$A$2:$A$514)=B3)) -> 457700 | E3: =SUMPRODUCT(('📋 Raw Data'!$H$2:$H$514)*(('📋 Raw Data'!$A$2:$A$514)=B3)) -> 6164 | F3: =SUMPRODUCT(('📋 Raw Data'!$I$2:$I$514)*(('📋 Raw Data'!$A$2:$A$514)=B3)) -> 237268 | G3: =SUMPRODUCT(('📋 Raw Data'!$F$2:$F$514)*(('📋 Raw Data'!$A$2:$A$514)=B3)) -> 5796 | J3: =SUMPRODUCT(('📋 Raw Data'!$K$2:$K$514)*(('📋 Raw Data'!$A$2:$A$514)=B3)*(('📋 Raw Data'!$E$2:$E$514)="M-Pesa")) -> 128800 | K3: =AVERAGE(J3:J3) -> 128800 | L3: =SUMPRODUCT(('📋 Raw Data'!$K$2:$K$514)*(('📋 Raw Data'!$A$2:$A$514)=B3)*(('📋 Raw Data'!$E$2:$E$514)="e-Mola")) -> 144900 | M3: =AVERAGE(L3:L3) -> 144900 | N3: =SUMPRODUCT(('📋 Raw Data'!$K$2:$K$514)*(('📋 Raw Data'!$A$2:$A$514)=B3)*(('📋 Raw Data'!$E$2:$E$514)="Numerário")) -> 184000 | O3: =AVERAGE(N3:N3) -> 184000
B4: 46083 | C4: =TEXT(B4,"MMM") -> Mar | D4: =SUMPRODUCT(('📋 Raw Data'!$K$2:$K$514)*(('📋 Raw Data'!$A$2:$A$514)=B4)) -> 335800 | E4: =SUMPRODUCT(('📋 Raw Data'!$H$2:$H$514)*(('📋 Raw Data'!$A$2:$A$514)=B4)) -> 7360 | F4: =SUMPRODUCT(('📋 Raw Data'!$I$2:$I$514)*(('📋 Raw Data'!$A$2:$A$514)=B4)) -> 154376 | G4: =SUMPRODUCT(('📋 Raw Data'!$F$2:$F$514)*(('📋 Raw Data'!$A$2:$A$514)=B4)) -> 5704 | J4: =SUMPRODUCT(('📋 Raw Data'!$K$2:$K$514)*(('📋 Raw Data'!$A$2:$A$514)=B4)*(('📋 Raw Data'!$E$2:$E$514)="M-Pesa")) -> 230000 | K4: =AVERAGE(J3:J4) -> 179400 | L4: =SUMPRODUCT(('📋 Raw Data'!$K$2:$K$514)*(('📋 Raw Data'!$A$2:$A$514)=B4)*(('📋 Raw Data'!$E$2:$E$514)="e-Mola")) -> 36800 | M4: =AVERAGE(L3:L4) -> 90850 | N4: =SUMPRODUCT(('📋 Raw Data'!$K$2:$K$514)*(('📋 Raw Data'!$A$2:$A$514)=B4)*(('📋 Raw Data'!$E$2:$E$514)="Numerário")) -> 69000 | O4: =AVERAGE(N3:N4) -> 126500
B5: 46084 | C5: =TEXT(B5,"MMM") -> Mar | D5: =SUMPRODUCT(('📋 Raw Data'!$K$2:$K$514)*(('📋 Raw Data'!$A$2:$A$514)=B5)) -> 340400 | E5: =SUMPRODUCT(('📋 Raw Data'!$H$2:$H$514)*(('📋 Raw Data'!$A$2:$A$514)=B5)) -> 6900 | F5: =SUMPRODUCT(('📋 Raw Data'!$I$2:$I$514)*(('📋 Raw Data'!$A$2:$A$514)=B5)) -> 261924 | G5: =SUMPRODUCT(('📋 Raw Data'!$F$2:$F$514)*(('📋 Raw Data'!$A$2:$A$514)=B5)) -> 4048 | J5: =SUMPRODUCT(('📋 Raw Data'!$K$2:$K$514)*(('📋 Raw Data'!$A$2:$A$514)=B5)*(('📋 Raw Data'!$E$2:$E$514)="M-Pesa")) -> 48300 | K5: =AVERAGE(J3:J5) -> 135700 | L5: =SUMPRODUCT(('📋 Raw Data'!$K$2:$K$514)*(('📋 Raw Data'!$A$2:$A$514)=B5)*(('📋 Raw Data'!$E$2:$E$514)="e-Mola")) -> 216200 | M5: =AVERAGE(L3:L5) -> 132633.33 | N5: =SUMPRODUCT(('📋 Raw Data'!$K$2:$K$514)*(('📋 Raw Data'!$A$2:$A$514)=B5)*(('📋 Raw Data'!$E$2:$E$514)="Numerário")) -> 75900 | O5: =AVERAGE(N3:N5) -> 109633.33
B6: 46085 | C6: =TEXT(B6,"MMM") -> Mar | D6: =SUMPRODUCT(('📋 Raw Data'!$K$2:$K$514)*(('📋 Raw Data'!$A$2:$A$514)=B6)) -> 330740 | E6: =SUMPRODUCT(('📋 Raw Data'!$H$2:$H$514)*(('📋 Raw Data'!$A$2:$A$514)=B6)) -> 8280 | F6: =SUMPRODUCT(('📋 Raw Data'!$I$2:$I$514)*(('📋 Raw Data'!$A$2:$A$514)=B6)) -> 245364 | G6: =SUMPRODUCT(('📋 Raw Data'!$F$2:$F$514)*(('📋 Raw Data'!$A$2:$A$514)=B6)) -> 6164 | J6: =SUMPRODUCT(('📋 Raw Data'!$K$2:$K$514)*(('📋 Raw Data'!$A$2:$A$514)=B6)*(('📋 Raw Data'!$E$2:$E$514)="M-Pesa")) -> 92000 | K6: =AVERAGE(J3:J6) -> 124775 | L6: =SUMPRODUCT(('📋 Raw Data'!$K$2:$K$514)*(('📋 Raw Data'!$A$2:$A$514)=B6)*(('📋 Raw Data'!$E$2:$E$514)="e-Mola")) -> 119140 | M6: =AVERAGE(L3:L6) -> 129260 | N6: =SUMPRODUCT(('📋 Raw Data'!$K$2:$K$514)*(('📋 Raw Data'!$A$2:$A$514)=B6)*(('📋 Raw Data'!$E$2:$E$514)="Numerário")) -> 119600 | O6: =AVERAGE(N3:N6) -> 112125
B7: 46086 | C7: =TEXT(B7,"MMM") -> Mar | D7: =SUMPRODUCT(('📋 Raw Data'!$K$2:$K$514)*(('📋 Raw Data'!$A$2:$A$514)=B7)) -> 270480 | E7: =SUMPRODUCT(('📋 Raw Data'!$H$2:$H$514)*(('📋 Raw Data'!$A$2:$A$514)=B7)) -> 5796 | F7: =SUMPRODUCT(('📋 Raw Data'!$I$2:$I$514)*(('📋 Raw Data'!$A$2:$A$514)=B7)) -> 155296 | G7: =SUMPRODUCT(('📋 Raw Data'!$F$2:$F$514)*(('📋 Raw Data'!$A$2:$A$514)=B7)) -> 4876 | J7: =SUMPRODUCT(('📋 Raw Data'!$K$2:$K$514)*(('📋 Raw Data'!$A$2:$A$514)=B7)*(('📋 Raw Data'!$E$2:$E$514)="M-Pesa")) -> 128800 | K7: =AVERAGE(J3:J7) -> 125580 | L7: =SUMPRODUCT(('📋 Raw Data'!$K$2:$K$514)*(('📋 Raw Data'!$A$2:$A$514)=B7)*(('📋 Raw Data'!$E$2:$E$514)="e-Mola")) -> 89700 | M7: =AVERAGE(L3:L7) -> 121348 | N7: =SUMPRODUCT(('📋 Raw Data'!$K$2:$K$514)*(('📋 Raw Data'!$A$2:$A$514)=B7)*(('📋 Raw Data'!$E$2:$E$514)="Numerário")) -> 51980 | O7: =AVERAGE(N3:N7) -> 100096
B8: 46087 | C8: =TEXT(B8,"MMM") -> Mar | D8: =SUMPRODUCT(('📋 Raw Data'!$K$2:$K$514)*(('📋 Raw Data'!$A$2:$A$514)=B8)) -> 202400 | E8: =SUMPRODUCT(('📋 Raw Data'!$H$2:$H$514)*(('📋 Raw Data'!$A$2:$A$514)=B8)) -> 4784 | F8: =SUMPRODUCT(('📋 Raw Data'!$I$2:$I$514)*(('📋 Raw Data'!$A$2:$A$514)=B8)) -> 152812 | G8: =SUMPRODUCT(('📋 Raw Data'!$F$2:$F$514)*(('📋 Raw Data'!$A$2:$A$514)=B8)) -> 5060 | J8: =SUMPRODUCT(('📋 Raw Data'!$K$2:$K$514)*(('📋 Raw Data'!$A$2:$A$514)=B8)*(('📋 Raw Data'!$E$2:$E$514)="M-Pesa")) -> 0 | K8: =AVERAGE(J3:J8) -> 104650 | L8: =SUMPRODUCT(('📋 Raw Data'!$K$2:$K$514)*(('📋 Raw Data'!$A$2:$A$514)=B8)*(('📋 Raw Data'!$E$2:$E$514)="e-Mola")) -> 200100 | M8: =AVERAGE(L3:L8) -> 134473.33 | N8: =SUMPRODUCT(('📋 Raw Data'!$K$2:$K$514)*(('📋 Raw Data'!$A$2:$A$514)=B8)*(('📋 Raw Data'!$E$2:$E$514)="Numerário")) -> 2300 | O8: =AVERAGE(N3:N8) -> 83796.667
B9: 46088 | C9: =TEXT(B9,"MMM") -> Mar | D9: =SUMPRODUCT(('📋 Raw Data'!$K$2:$K$514)*(('📋 Raw Data'!$A$2:$A$514)=B9)) -> 356040 | E9: =SUMPRODUCT(('📋 Raw Data'!$H$2:$H$514)*(('📋 Raw Data'!$A$2:$A$514)=B9)) -> 5244 | F9: =SUMPRODUCT(('📋 Raw Data'!$I$2:$I$514)*(('📋 Raw Data'!$A$2:$A$514)=B9)) -> 176732 | G9: =SUMPRODUCT(('📋 Raw Data'!$F$2:$F$514)*(('📋 Raw Data'!$A$2:$A$514)=B9)) -> 6624 | J9: =SUMPRODUCT(('📋 Raw Data'!$K$2:$K$514)*(('📋 Raw Data'!$A$2:$A$514)=B9)*(('📋 Raw Data'!$E$2:$E$514)="M-Pesa")) -> 209760 | K9: =AVERAGE(J3:J9) -> 119665.71 | L9: =SUMPRODUCT(('📋 Raw Data'!$K$2:$K$514)*(('📋 Raw Data'!$A$2:$A$514)=B9)*(('📋 Raw Data'!$E$2:$E$514)="e-Mola")) -> 95680 | M9: =AVERAGE(L3:L9) -> 128931.43 | N9: =SUMPRODUCT(('📋 Raw Data'!$K$2:$K$514)*(('📋 Raw Data'!$A$2:$A$514)=B9)*(('📋 Raw Data'!$E$2:$E$514)="Numerário")) -> 50600 | O9: =AVERAGE(N3:N9) -> 79054.286
B10: 46089 | C10: =TEXT(B10,"MMM") -> Mar | D10: =SUMPRODUCT(('📋 Raw Data'!$K$2:$K$514)*(('📋 Raw Data'!$A$2:$A$514)=B10)) -> 402040 | E10: =SUMPRODUCT(('📋 Raw Data'!$H$2:$H$514)*(('📋 Raw Data'!$A$2:$A$514)=B10)) -> 6532 | F10: =SUMPRODUCT(('📋 Raw Data'!$I$2:$I$514)*(('📋 Raw Data'!$A$2:$A$514)=B10)) -> 220800 | G10: =SUMPRODUCT(('📋 Raw Data'!$F$2:$F$514)*(('📋 Raw Data'!$A$2:$A$514)=B10)) -> 5612 | J10: =SUMPRODUCT(('📋 Raw Data'!$K$2:$K$514)*(('📋 Raw Data'!$A$2:$A$514)=B10)*(('📋 Raw Data'!$E$2:$E$514)="M-Pesa")) -> 113160 | K10: =AVERAGE(J4:J10) -> 117431.43 | L10: =SUMPRODUCT(('📋 Raw Data'!$K$2:$K$514)*(('📋 Raw Data'!$A$2:$A$514)=B10)*(('📋 Raw Data'!$E$2:$E$514)="e-Mola")) -> 104880 | M10: =AVERAGE(L4:L10) -> 123214.29 | N10: =SUMPRODUCT(('📋 Raw Data'!$K$2:$K$514)*(('📋 Raw Data'!$A$2:$A$514)=B10)*(('📋 Raw Data'!$E$2:$E$514)="Numerário")) -> 184000 | O10: =AVERAGE(N4:N10) -> 79054.286
B11: 46090 | C11: =TEXT(B11,"MMM") -> Mar | D11: =SUMPRODUCT(('📋 Raw Data'!$K$2:$K$514)*(('📋 Raw Data'!$A$2:$A$514)=B11)) -> 571780 | E11: =SUMPRODUCT(('📋 Raw Data'!$H$2:$H$514)*(('📋 Raw Data'!$A$2:$A$514)=B11)) -> 4692 | F11: =SUMPRODUCT(('📋 Raw Data'!$I$2:$I$514)*(('📋 Raw Data'!$A$2:$A$514)=B11)) -> 127144 | G11: =SUMPRODUCT(('📋 Raw Data'!$F$2:$F$514)*(('📋 Raw Data'!$A$2:$A$514)=B11)) -> 8004 | J11: =SUMPRODUCT(('📋 Raw Data'!$K$2:$K$514)*(('📋 Raw Data'!$A$2:$A$514)=B11)*(('📋 Raw Data'!$E$2:$E$514)="M-Pesa")) -> 414000 | K11: =AVERAGE(J5:J11) -> 143717.14 | L11: =SUMPRODUCT(('📋 Raw Data'!$K$2:$K$514)*(('📋 Raw Data'!$A$2:$A$514)=B11)*(('📋 Raw Data'!$E$2:$E$514)="e-Mola")) -> 157780 | M11: =AVERAGE(L5:L11) -> 140497.14 | N11: =SUMPRODUCT(('📋 Raw Data'!$K$2:$K$514)*(('📋 Raw Data'!$A$2:$A$514)=B11)*(('📋 Raw Data'!$E$2:$E$514)="Numerário")) -> 0 | O11: =AVERAGE(N5:N11) -> 69197.143
B12: 46091 | C12: =TEXT(B12,"MMM") -> Mar | D12: =SUMPRODUCT(('📋 Raw Data'!$K$2:$K$514)*(('📋 Raw Data'!$A$2:$A$514)=B12)) -> 312800 | E12: =SUMPRODUCT(('📋 Raw Data'!$H$2:$H$514)*(('📋 Raw Data'!$A$2:$A$514)=B12)) -> 4416 | F12: =SUMPRODUCT(('📋 Raw Data'!$I$2:$I$514)*(('📋 Raw Data'!$A$2:$A$514)=B12)) -> 132664 | G12: =SUMPRODUCT(('📋 Raw Data'!$F$2:$F$514)*(('📋 Raw Data'!$A$2:$A$514)=B12)) -> 3772 | J12: =SUMPRODUCT(('📋 Raw Data'!$K$2:$K$514)*(('📋 Raw Data'!$A$2:$A$514)=B12)*(('📋 Raw Data'!$E$2:$E$514)="M-Pesa")) -> 0 | K12: =AVERAGE(J6:J12) -> 136817.14 | L12: =SUMPRODUCT(('📋 Raw Data'!$K$2:$K$514)*(('📋 Raw Data'!$A$2:$A$514)=B12)*(('📋 Raw Data'!$E$2:$E$514)="e-Mola")) -> 161000 | M12: =AVERAGE(L6:L12) -> 132611.43 | N12: =SUMPRODUCT(('📋 Raw Data'!$K$2:$K$514)*(('📋 Raw Data'!$A$2:$A$514)=B12)*(('📋 Raw Data'!$E$2:$E$514)="Numerário")) -> 151800 | O12: =AVERAGE(N6:N12) -> 80040
B13: 46092 | C13: =TEXT(B13,"MMM") -> Mar | D13: =SUMPRODUCT(('📋 Raw Data'!$K$2:$K$514)*(('📋 Raw Data'!$A$2:$A$514)=B13)) -> 324300 | E13: =SUMPRODUCT(('📋 Raw Data'!$H$2:$H$514)*(('📋 Raw Data'!$A$2:$A$514)=B13)) -> 6256 | F13: =SUMPRODUCT(('📋 Raw Data'!$I$2:$I$514)*(('📋 Raw Data'!$A$2:$A$514)=B13)) -> 84640 | G13: =SUMPRODUCT(('📋 Raw Data'!$F$2:$F$514)*(('📋 Raw Data'!$A$2:$A$514)=B13)) -> 7452 | J13: =SUMPRODUCT(('📋 Raw Data'!$K$2:$K$514)*(('📋 Raw Data'!$A$2:$A$514)=B13)*(('📋 Raw Data'!$E$2:$E$514)="M-Pesa")) -> 0 | K13: =AVERAGE(J7:J13) -> 123674.29 | L13: =SUMPRODUCT(('📋 Raw Data'!$K$2:$K$514)*(('📋 Raw Data'!$A$2:$A$514)=B13)*(('📋 Raw Data'!$E$2:$E$514)="e-Mola")) -> 161000 | M13: =AVERAGE(L7:L13) -> 138591.43 | N13: =SUMPRODUCT(('📋 Raw Data'!$K$2:$K$514)*(('📋 Raw Data'!$A$2:$A$514)=B13)*(('📋 Raw Data'!$E$2:$E$514)="Numerário")) -> 163300 | O13: =AVERAGE(N7:N13) -> 86282.857
B14: 46093 | C14: =TEXT(B14,"MMM") -> Mar | D14: =SUMPRODUCT(('📋 Raw Data'!$K$2:$K$514)*(('📋 Raw Data'!$A$2:$A$514)=B14)) -> 415380 | E14: =SUMPRODUCT(('📋 Raw Data'!$H$2:$H$514)*(('📋 Raw Data'!$A$2:$A$514)=B14)) -> 5796 | F14: =SUMPRODUCT(('📋 Raw Data'!$I$2:$I$514)*(('📋 Raw Data'!$A$2:$A$514)=B14)) -> 116196 | G14: =SUMPRODUCT(('📋 Raw Data'!$F$2:$F$514)*(('📋 Raw Data'!$A$2:$A$514)=B14)) -> 6716 | J14: =SUMPRODUCT(('📋 Raw Data'!$K$2:$K$514)*(('📋 Raw Data'!$A$2:$A$514)=B14)*(('📋 Raw Data'!$E$2:$E$514)="M-Pesa")) -> 0 | K14: =AVERAGE(J8:J14) -> 105274.29 | L14: =SUMPRODUCT(('📋 Raw Data'!$K$2:$K$514)*(('📋 Raw Data'!$A$2:$A$514)=B14)*(('📋 Raw Data'!$E$2:$E$514)="e-Mola")) -> 216660 | M14: =AVERAGE(L8:L14) -> 156728.57 | N14: =SUMPRODUCT(('📋 Raw Data'!$K$2:$K$514)*(('📋 Raw Data'!$A$2:$A$514)=B14)*(('📋 Raw Data'!$E$2:$E$514)="Numerário")) -> 198720 | O14: =AVERAGE(N8:N14) -> 107245.71
B15: 46094 | C15: =TEXT(B15,"MMM") -> Mar | D15: =SUMPRODUCT(('📋 Raw Data'!$K$2:$K$514)*(('📋 Raw Data'!$A$2:$A$514)=B15)) -> 146280 | E15: =SUMPRODUCT(('📋 Raw Data'!$H$2:$H$514)*(('📋 Raw Data'!$A$2:$A$514)=B15)) -> 5244 | F15: =SUMPRODUCT(('📋 Raw Data'!$I$2:$I$514)*(('📋 Raw Data'!$A$2:$A$514)=B15)) -> 86940 | G15: =SUMPRODUCT(('📋 Raw Data'!$F$2:$F$514)*(('📋 Raw Data'!$A$2:$A$514)=B15)) -> 2852 | J15: =SUMPRODUCT(('📋 Raw Data'!$K$2:$K$514)*(('📋 Raw Data'!$A$2:$A$514)=B15)*(('📋 Raw Data'!$E$2:$E$514)="M-Pesa")) -> 0 | K15: =AVERAGE(J9:J15) -> 105274.29 | L15: =SUMPRODUCT(('📋 Raw Data'!$K$2:$K$514)*(('📋 Raw Data'!$A$2:$A$514)=B15)*(('📋 Raw Data'!$E$2:$E$514)="e-Mola")) -> 75900 | M15: =AVERAGE(L9:L15) -> 138985.71 | N15: =SUMPRODUCT(('📋 Raw Data'!$K$2:$K$514)*(('📋 Raw Data'!$A$2:$A$514)=B15)*(('📋 Raw Data'!$E$2:$E$514)="Numerário")) -> 70380 | O15: =AVERAGE(N9:N15) -> 116971.43
B16: 46095 | C16: =TEXT(B16,"MMM") -> Mar | D16: =SUMPRODUCT(('📋 Raw Data'!$K$2:$K$514)*(('📋 Raw Data'!$A$2:$A$514)=B16)) -> 240580 | E16: =SUMPRODUCT(('📋 Raw Data'!$H$2:$H$514)*(('📋 Raw Data'!$A$2:$A$514)=B16)) -> 4048 | F16: =SUMPRODUCT(('📋 Raw Data'!$I$2:$I$514)*(('📋 Raw Data'!$A$2:$A$514)=B16)) -> 51704 | G16: =SUMPRODUCT(('📋 Raw Data'!$F$2:$F$514)*(('📋 Raw Data'!$A$2:$A$514)=B16)) -> 5060 | J16: =SUMPRODUCT(('📋 Raw Data'!$K$2:$K$514)*(('📋 Raw Data'!$A$2:$A$514)=B16)*(('📋 Raw Data'!$E$2:$E$514)="M-Pesa")) -> 0 | K16: =AVERAGE(J10:J16) -> 75308.571 | L16: =SUMPRODUCT(('📋 Raw Data'!$K$2:$K$514)*(('📋 Raw Data'!$A$2:$A$514)=B16)*(('📋 Raw Data'!$E$2:$E$514)="e-Mola")) -> 178480 | M16: =AVERAGE(L10:L16) -> 150814.29 | N16: =SUMPRODUCT(('📋 Raw Data'!$K$2:$K$514)*(('📋 Raw Data'!$A$2:$A$514)=B16)*(('📋 Raw Data'!$E$2:$E$514)="Numerário")) -> 62100 | O16: =AVERAGE(N10:N16) -> 118614.29
B17: 46096 | C17: =TEXT(B17,"MMM") -> Mar | D17: =SUMPRODUCT(('📋 Raw Data'!$K$2:$K$514)*(('📋 Raw Data'!$A$2:$A$514)=B17)) -> 326600 | E17: =SUMPRODUCT(('📋 Raw Data'!$H$2:$H$514)*(('📋 Raw Data'!$A$2:$A$514)=B17)) -> 5980 | F17: =SUMPRODUCT(('📋 Raw Data'!$I$2:$I$514)*(('📋 Raw Data'!$A$2:$A$514)=B17)) -> 176548 | G17: =SUMPRODUCT(('📋 Raw Data'!$F$2:$F$514)*(('📋 Raw Data'!$A$2:$A$514)=B17)) -> 4876 | J17: =SUMPRODUCT(('📋 Raw Data'!$K$2:$K$514)*(('📋 Raw Data'!$A$2:$A$514)=B17)*(('📋 Raw Data'!$E$2:$E$514)="M-Pesa")) -> 9200 | K17: =AVERAGE(J11:J17) -> 60457.143 | L17: =SUMPRODUCT(('📋 Raw Data'!$K$2:$K$514)*(('📋 Raw Data'!$A$2:$A$514)=B17)*(('📋 Raw Data'!$E$2:$E$514)="e-Mola")) -> 124200 | M17: =AVERAGE(L11:L17) -> 153574.29 | N17: =SUMPRODUCT(('📋 Raw Data'!$K$2:$K$514)*(('📋 Raw Data'!$A$2:$A$514)=B17)*(('📋 Raw Data'!$E$2:$E$514)="Numerário")) -> 193200 | O17: =AVERAGE(N11:N17) -> 119928.57
B18: 46097 | C18: =TEXT(B18,"MMM") -> Mar | D18: =SUMPRODUCT(('📋 Raw Data'!$K$2:$K$514)*(('📋 Raw Data'!$A$2:$A$514)=B18)) -> 159160 | E18: =SUMPRODUCT(('📋 Raw Data'!$H$2:$H$514)*(('📋 Raw Data'!$A$2:$A$514)=B18)) -> 5704 | F18: =SUMPRODUCT(('📋 Raw Data'!$I$2:$I$514)*(('📋 Raw Data'!$A$2:$A$514)=B18)) -> 124752 | G18: =SUMPRODUCT(('📋 Raw Data'!$F$2:$F$514)*(('📋 Raw Data'!$A$2:$A$514)=B18)) -> 2944 | J18: =SUMPRODUCT(('📋 Raw Data'!$K$2:$K$514)*(('📋 Raw Data'!$A$2:$A$514)=B18)*(('📋 Raw Data'!$E$2:$E$514)="M-Pesa")) -> 0 | K18: =AVERAGE(J12:J18) -> 1314.2857 | L18: =SUMPRODUCT(('📋 Raw Data'!$K$2:$K$514)*(('📋 Raw Data'!$A$2:$A$514)=B18)*(('📋 Raw Data'!$E$2:$E$514)="e-Mola")) -> 55660 | M18: =AVERAGE(L12:L18) -> 138985.71 | N18: =SUMPRODUCT(('📋 Raw Data'!$K$2:$K$514)*(('📋 Raw Data'!$A$2:$A$514)=B18)*(('📋 Raw Data'!$E$2:$E$514)="Numerário")) -> 103500 | O18: =AVERAGE(N12:N18) -> 134714.29
B19: 46098 | C19: =TEXT(B19,"MMM") -> Mar | D19: =SUMPRODUCT(('📋 Raw Data'!$K$2:$K$514)*(('📋 Raw Data'!$A$2:$A$514)=B19)) -> 365700 | E19: =SUMPRODUCT(('📋 Raw Data'!$H$2:$H$514)*(('📋 Raw Data'!$A$2:$A$514)=B19)) -> 4784 | F19: =SUMPRODUCT(('📋 Raw Data'!$I$2:$I$514)*(('📋 Raw Data'!$A$2:$A$514)=B19)) -> 57776 | G19: =SUMPRODUCT(('📋 Raw Data'!$F$2:$F$514)*(('📋 Raw Data'!$A$2:$A$514)=B19)) -> 5152 | J19: =SUMPRODUCT(('📋 Raw Data'!$K$2:$K$514)*(('📋 Raw Data'!$A$2:$A$514)=B19)*(('📋 Raw Data'!$E$2:$E$514)="M-Pesa")) -> 0 | K19: =AVERAGE(J13:J19) -> 1314.2857 | L19: =SUMPRODUCT(('📋 Raw Data'!$K$2:$K$514)*(('📋 Raw Data'!$A$2:$A$514)=B19)*(('📋 Raw Data'!$E$2:$E$514)="e-Mola")) -> 179400 | M19: =AVERAGE(L13:L19) -> 141614.29 | N19: =SUMPRODUCT(('📋 Raw Data'!$K$2:$K$514)*(('📋 Raw Data'!$A$2:$A$514)=B19)*(('📋 Raw Data'!$E$2:$E$514)="Numerário")) -> 186300 | O19: =AVERAGE(N13:N19) -> 139642.86
B20: 46099 | C20: =TEXT(B20,"MMM") -> Mar | D20: =SUMPRODUCT(('📋 Raw Data'!$K$2:$K$514)*(('📋 Raw Data'!$A$2:$A$514)=B20)) -> 287960 | E20: =SUMPRODUCT(('📋 Raw Data'!$H$2:$H$514)*(('📋 Raw Data'!$A$2:$A$514)=B20)) -> 3496 | F20: =SUMPRODUCT(('📋 Raw Data'!$I$2:$I$514)*(('📋 Raw Data'!$A$2:$A$514)=B20)) -> 116288 | G20: =SUMPRODUCT(('📋 Raw Data'!$F$2:$F$514)*(('📋 Raw Data'!$A$2:$A$514)=B20)) -> 4232 | J20: =SUMPRODUCT(('📋 Raw Data'!$K$2:$K$514)*(('📋 Raw Data'!$A$2:$A$514)=B20)*(('📋 Raw Data'!$E$2:$E$514)="M-Pesa")) -> 287960 | K20: =AVERAGE(J14:J20) -> 42451.429 | L20: =SUMPRODUCT(('📋 Raw Data'!$K$2:$K$514)*(('📋 Raw Data'!$A$2:$A$514)=B20)*(('📋 Raw Data'!$E$2:$E$514)="e-Mola")) -> 0 | M20: =AVERAGE(L14:L20) -> 118614.29 | N20: =SUMPRODUCT(('📋 Raw Data'!$K$2:$K$514)*(('📋 Raw Data'!$A$2:$A$514)=B20)*(('📋 Raw Data'!$E$2:$E$514)="Numerário")) -> 0 | O20: =AVERAGE(N14:N20) -> 116314.29
... B94: 46173 | C94: =TEXT(B94,"MMM") -> May | D94: =SUMPRODUCT(('📋 Raw Data'!$K$2:$K$514)*(('📋 Raw Data'!$A$2:$A$514)=B94)) -> 454020 | E94: =SUMPRODUCT(('📋 Raw Data'!$H$2:$H$514)*(('📋 Raw Data'!$A$2:$A$514)=B94)) -> 5244 | F94: =SUMPRODUCT(('📋 Raw Data'!$I$2:$I$514)*(('📋 Raw Data'!$A$2:$A$514)=B94)) -> 122820 | G94: =SUMPRODUCT(('📋 Raw Data'!$F$2:$F$514)*(('📋 Raw Data'!$A$2:$A$514)=B94)) -> 6808 | J94: =SUMPRODUCT(('📋 Raw Data'!$K$2:$K$514)*(('📋 Raw Data'!$A$2:$A$514)=B94)*(('📋 Raw Data'!$E$2:$E$514)="M-Pesa")) -> 90620 | K94: =AVERAGE(J88:J94) -> 92000 | L94: =SUMPRODUCT(('📋 Raw Data'!$K$2:$K$514)*(('📋 Raw Data'!$A$2:$A$514)=B94)*(('📋 Raw Data'!$E$2:$E$514)="e-Mola")) -> 82800 | M94: =AVERAGE(L88:L94) -> 40742.857 | N94: =SUMPRODUCT(('📋 Raw Data'!$K$2:$K$514)*(('📋 Raw Data'!$A$2:$A$514)=B94)*(('📋 Raw Data'!$E$2:$E$514)="Numerário")) -> 280600 | O94: =AVERAGE(N88:N94) -> 95351.429

Sheet 💳 By Payment
B2: 💳 MOZCHAPA100 — Revenue by Payment Method
B4: 💰 Revenue by Payment Method — Month-on-Month
B5: Payment Method | C5: Mar 2026 | D5: Apr 2026 | E5: May 2026 | F5: Apr vs Mar % | G5: May vs Apr % | H5: Apr vs Mar Abs | I5: May vs Apr Abs | J5: May Share %
B6: M-Pesa | C6: =SUMPRODUCT(('📋 Raw Data'!$K$2:$K$514)*(YEAR('📋 Raw Data'!$A$2:$A$514)=2026)*(MONTH('📋 Raw Data'!$A$2:$A$514)=3)*('📋 Raw Data'!$E$2:$E$514="M-Pesa")) -> 2963780 | D6: =SUMPRODUCT(('📋 Raw Data'!$K$2:$K$514)*(YEAR('📋 Raw Data'!$A$2:$A$514)=2026)*(MONTH('📋 Raw Data'!$A$2:$A$514)=4)*('📋 Raw Data'!$E$2:$E$514="M-Pesa")) -> 2950900 | E6: =SUMPRODUCT(('📋 Raw Data'!$K$2:$K$514)*(YEAR('📋 Raw Data'!$A$2:$A$514)=2026)*(MONTH('📋 Raw Data'!$A$2:$A$514)=5)*('📋 Raw Data'!$E$2:$E$514="M-Pesa")) -> 3825820 | F6: =D6/C6-1 -> -0.0043458016 | G6: =E6/D6-1 -> 0.2964926 | H6: =D6-C6 -> -12880 | I6: =E6-D6 -> 874920 | J6: =E6/$E$9 -> 0.39813308
B7: Numerário | C7: =SUMPRODUCT(('📋 Raw Data'!$K$2:$K$514)*(YEAR('📋 Raw Data'!$A$2:$A$514)=2026)*(MONTH('📋 Raw Data'!$A$2:$A$514)=3)*('📋 Raw Data'!$E$2:$E$514="Numerário")) -> 2971140 | D7: =SUMPRODUCT(('📋 Raw Data'!$K$2:$K$514)*(YEAR('📋 Raw Data'!$A$2:$A$514)=2026)*(MONTH('📋 Raw Data'!$A$2:$A$514)=4)*('📋 Raw Data'!$E$2:$E$514="Numerário")) -> 4208080 | E7: =SUMPRODUCT(('📋 Raw Data'!$K$2:$K$514)*(YEAR('📋 Raw Data'!$A$2:$A$514)=2026)*(MONTH('📋 Raw Data'!$A$2:$A$514)=5)*('📋 Raw Data'!$E$2:$E$514="Numerário")) -> 3124320 | F7: =D7/C7-1 -> 0.41631832 | G7: =E7/D7-1 -> -0.25754263 | H7: =D7-C7 -> 1236940 | I7: =E7-D7 -> -1083760 | J7: =E7/$E$9 -> 0.32513164
B8: e-Mola | C8: =SUMPRODUCT(('📋 Raw Data'!$K$2:$K$514)*(YEAR('📋 Raw Data'!$A$2:$A$514)=2026)*(MONTH('📋 Raw Data'!$A$2:$A$514)=3)*('📋 Raw Data'!$E$2:$E$514="e-Mola")) -> 4462920 | D8: =SUMPRODUCT(('📋 Raw Data'!$K$2:$K$514)*(YEAR('📋 Raw Data'!$A$2:$A$514)=2026)*(MONTH('📋 Raw Data'!$A$2:$A$514)=4)*('📋 Raw Data'!$E$2:$E$514="e-Mola")) -> 2930660 | E8: =SUMPRODUCT(('📋 Raw Data'!$K$2:$K$514)*(YEAR('📋 Raw Data'!$A$2:$A$514)=2026)*(MONTH('📋 Raw Data'!$A$2:$A$514)=5)*('📋 Raw Data'!$E$2:$E$514="e-Mola")) -> 2659260 | F8: =D8/C8-1 -> -0.34333127 | G8: =E8/D8-1 -> -0.092607126 | H8: =D8-C8 -> -1532260 | I8: =E8-D8 -> -271400 | J8: =E8/$E$9 -> 0.27673528
B9: TOTAL | C9: =SUM(C6:C8) -> 10397840 | D9: =SUM(D6:D8) -> 10089640 | E9: =SUM(E6:E8) -> 9609400 | F9: =D9/C9-1 -> -0.029640772 | G9: =E9/D9-1 -> -0.047597337 | H9: =D9-C9 -> -308200 | I9: =E9-D9 -> -480240
B11: 💡 TIP FOR STUDENTS: Sort column E (May Rev) Z→A to see top performers. Sort A→Z to see bottom performers. Use conditional formatting on column F to colour-code growth vs decline.

Sheet 🏆 Performers
B2: 🏆 MOZCHAPA100 — Route Performers (May 2026)
B4: 🥇 ALL ROUTES — Ranked by May Revenue
B5: Route | C5: Mar Rev | D5: Apr Rev | E5: May Rev | F5: May vs Apr % | G5: May vs Apr Abs
B6: 4️⃣ Maputo Centro - Matola | C6: =SUMPRODUCT(('📋 Raw Data'!$K$2:$K$514)*(YEAR('📋 Raw Data'!$A$2:$A$514)=2026)*(MONTH('📋 Raw Data'!$A$2:$A$514)=3)*('📋 Raw Data'!$D$2:$D$514="Maputo Centro - Matola")) -> 1937060 | D6: =SUMPRODUCT(('📋 Raw Data'!$K$2:$K$514)*(YEAR('📋 Raw Data'!$A$2:$A$514)=2026)*(MONTH('📋 Raw Data'!$A$2:$A$514)=4)*('📋 Raw Data'!$D$2:$D$514="Maputo Centro - Matola")) -> 1413580 | E6: =SUMPRODUCT(('📋 Raw Data'!$K$2:$K$514)*(YEAR('📋 Raw Data'!$A$2:$A$514)=2026)*(MONTH('📋 Raw Data'!$A$2:$A$514)=5)*('📋 Raw Data'!$D$2:$D$514="Maputo Centro - Matola")) -> 2113700 | F6: =E6/D6-1 -> 0.49528148 | G6: =E6-D6 -> 700120
B7: 5️⃣ Matola - Boane | C7: =SUMPRODUCT(('📋 Raw Data'!$K$2:$K$514)*(YEAR('📋 Raw Data'!$A$2:$A$514)=2026)*(MONTH('📋 Raw Data'!$A$2:$A$514)=3)*('📋 Raw Data'!$D$2:$D$514="Matola - Boane")) -> 3084300 | D7: =SUMPRODUCT(('📋 Raw Data'!$K$2:$K$514)*(YEAR('📋 Raw Data'!$A$2:$A$514)=2026)*(MONTH('📋 Raw Data'!$A$2:$A$514)=4)*('📋 Raw Data'!$D$2:$D$514="Matola - Boane")) -> 1280180 | E7: =SUMPRODUCT(('📋 Raw Data'!$K$2:$K$514)*(YEAR('📋 Raw Data'!$A$2:$A$514)=2026)*(MONTH('📋 Raw Data'!$A$2:$A$514)=5)*('📋 Raw Data'!$D$2:$D$514="Matola - Boane")) -> 1717640 | F7: =E7/D7-1 -> 0.34171757 | G7: =E7-D7 -> 437460
B8: 🥇 Machava - Marracuene | C8: =SUMPRODUCT(('📋 Raw Data'!$K$2:$K$514)*(YEAR('📋 Raw Data'!$A$2:$A$514)=2026)*(MONTH('📋 Raw Data'!$A$2:$A$514)=3)*('📋 Raw Data'!$D$2:$D$514="Machava - Marracuene")) -> 1754900 | D8: =SUMPRODUCT(('📋 Raw Data'!$K$2:$K$514)*(YEAR('📋 Raw Data'!$A$2:$A$514)=2026)*(MONTH('📋 Raw Data'!$A$2:$A$514)=4)*('📋 Raw Data'!$D$2:$D$514="Machava - Marracuene")) -> 1872660 | E8: =SUMPRODUCT(('📋 Raw Data'!$K$2:$K$514)*(YEAR('📋 Raw Data'!$A$2:$A$514)=2026)*(MONTH('📋 Raw Data'!$A$2:$A$514)=5)*('📋 Raw Data'!$D$2:$D$514="Machava - Marracuene")) -> 1925100 | F8: =E8/D8-1 -> 0.028002948 | G8: =E8-D8 -> 52440
B9: 🥉 Maputo Centro - Machava | C9: =SUMPRODUCT(('📋 Raw Data'!$K$2:$K$514)*(YEAR('📋 Raw Data'!$A$2:$A$514)=2026)*(MONTH('📋 Raw Data'!$A$2:$A$514)=3)*('📋 Raw Data'!$D$2:$D$514="Maputo Centro - Machava")) -> 1552500 | D9: =SUMPRODUCT(('📋 Raw Data'!$K$2:$K$514)*(YEAR('📋 Raw Data'!$A$2:$A$514)=2026)*(MONTH('📋 Raw Data'!$A$2:$A$514)=4)*('📋 Raw Data'!$D$2:$D$514="Maputo Centro - Machava")) -> 2281600 | E9: =SUMPRODUCT(('📋 Raw Data'!$K$2:$K$514)*(YEAR('📋 Raw Data'!$A$2:$A$514)=2026)*(MONTH('📋 Raw Data'!$A$2:$A$514)=5)*('📋 Raw Data'!$D$2:$D$514="Maputo Centro - Machava")) -> 2110940 | F9: =E9/D9-1 -> -0.074798387 | G9: =E9-D9 -> -170660
B10: 🥈 Maputo Centro - KaMavota | C10: =SUMPRODUCT(('📋 Raw Data'!$K$2:$K$514)*(YEAR('📋 Raw Data'!$A$2:$A$514)=2026)*(MONTH('📋 Raw Data'!$A$2:$A$514)=3)*('📋 Raw Data'!$D$2:$D$514="Maputo Centro - KaMavota")) -> 2069080 | D10: =SUMPRODUCT(('📋 Raw Data'!$K$2:$K$514)*(YEAR('📋 Raw Data'!$A$2:$A$514)=2026)*(MONTH('📋 Raw Data'!$A$2:$A$514)=4)*('📋 Raw Data'!$D$2:$D$514="Maputo Centro - KaMavota")) -> 3241620 | E10: =SUMPRODUCT(('📋 Raw Data'!$K$2:$K$514)*(YEAR('📋 Raw Data'!$A$2:$A$514)=2026)*(MONTH('📋 Raw Data'!$A$2:$A$514)=5)*('📋 Raw Data'!$D$2:$D$514="Maputo Centro - KaMavota")) -> 1742020 | F10: =E10/D10-1 -> -0.4626082 | G10: =E10-D10 -> -1499600
B12: 💡 TIP FOR STUDENTS: Sort column E (May Rev) Z→A to see top performers. Sort A→Z to see bottom performers. Use conditional formatting on column F to colour-code growth vs decline.
